<?xml version="1.0"?>
<robot name="Pioneer_p3dx">
    <link name="base_link_gt">
        <inertial>
            <origin rpy="3.141528 3.144488 3.122322" xyz="-0.012881 -0.000822 0.138649" />
            <inertia izz="2.0906035900116" iyz="2.9803723463435e-16" iyy="1.9390720129013" ixx="1.9199999570847" ixy="1.3291859387186e-44" ixz="6.7551167532783e-30" />
            <mass value="16.0" />
        </inertial>
        <collision name="Pioneer_p3dx">
            <origin rpy="-3.139250 3.143255 2.176595" xyz="-0.149319 0.097791 0.121420" />
            <geometry>
                <box size="0.050035 0.055540 0.120014" />
            </geometry>
        </collision>
        <collision name="Pioneer_p3dx">
            <origin rpy="1.572298 3.144434 2.598432" xyz="0.151517 -0.068243 0.207239" />
            <geometry>
                <box size="0.055000 0.055000 0.050100" />
            </geometry>
        </collision>
        <collision name="Pioneer_p3dx">
            <origin rpy="1.573177 3.143744 2.249365" xyz="0.123780 -0.103515 0.207114" />
            <geometry>
                <box size="0.055000 0.055000 0.050100" />
            </geometry>
        </collision>
        <collision name="Pioneer_p3dx">
            <origin rpy="1.573338 3.139561 0.853060" xyz="-0.156179 -0.096490 0.206422" />
            <geometry>
                <box size="0.055000 0.055000 0.050100" />
            </geometry>
        </collision>
        <collision name="Pioneer_p3dx">
            <origin rpy="1.572534 3.138814 0.504616" xyz="-0.184187 -0.061773 0.206337" />
            <geometry>
                <box size="0.055000 0.055000 0.050100" />
            </geometry>
        </collision>
        <collision name="Pioneer_p3dx">
            <origin rpy="1.571503 3.138414 0.156034" xyz="-0.198660 -0.019547 0.206290" />
            <geometry>
                <box size="0.055000 0.055000 0.050100" />
            </geometry>
        </collision>
        <collision name="Pioneer_p3dx">
            <origin rpy="1.571217 3.144803 2.947012" xyz="-0.197800 0.025052 0.206288" />
            <geometry>
                <box size="0.055000 0.055000 0.050100" />
            </geometry>
        </collision>
        <collision name="Pioneer_p3dx">
            <origin rpy="1.572298 3.144429 2.598435" xyz="-0.181712 0.066690 0.206329" />
            <geometry>
                <box size="0.055000 0.055000 0.050100" />
            </geometry>
        </collision>
        <collision name="Pioneer_p3dx">
            <origin rpy="1.573206 3.143732 2.250684" xyz="-0.152371 0.100339 0.206410" />
            <geometry>
                <box size="0.055000 0.055000 0.050100" />
            </geometry>
        </collision>
        <collision name="Pioneer_p3dx">
            <origin rpy="3.138897 3.143237 -2.142979" xyz="0.129305 0.097257 0.207155" />
            <geometry>
                <box size="0.055000 0.055000 0.050100" />
            </geometry>
        </collision>
        <collision name="Pioneer_p3dx">
            <origin rpy="1.569550 3.144480 -2.711350" xyz="0.153210 0.066744 0.207221" />
            <geometry>
                <box size="0.055000 0.055000 0.050100" />
            </geometry>
        </collision>
        <collision name="Pioneer_p3dx">
            <origin rpy="1.571135 3.138889 0.154248" xyz="0.168455 0.018044 0.207279" />
            <geometry>
                <box size="0.055000 0.055000 0.050100" />
            </geometry>
        </collision>
        <collision name="Pioneer_p3dx">
            <origin rpy="-1.570522 3.144317 2.949240" xyz="0.167580 -0.026665 0.207286" />
            <geometry>
                <box size="0.055000 0.055000 0.050100" />
            </geometry>
        </collision>
        <collision name="Pioneer_p3dx">
            <origin rpy="-1.551005 4.709148 -0.039062" xyz="-0.015088 -0.000751 0.206780" />
            <geometry>
                <box size="0.050128 0.271710 0.274352" />
            </geometry>
        </collision>
        <collision name="Pioneer_p3dx">
            <origin rpy="-1.570792 3.138742 -0.019272" xyz="-0.267861 0.004085 0.054709" />
            <geometry>
                <box size="0.008461 0.030006 0.100002" />
            </geometry>
        </collision>
        <collision name="Pioneer_p3dx">
            <origin rpy="-1.573311 3.142809 -2.053710" xyz="-0.163520 -0.169173 0.055028" />
            <geometry>
                <box size="0.008461 0.030008 0.111805" />
            </geometry>
        </collision>
        <collision name="Pioneer_p3dx">
            <origin rpy="1.572393 3.139174 0.521148" xyz="-0.240356 -0.094287 0.054800" />
            <geometry>
                <box size="0.008459 0.030008 0.116621" />
            </geometry>
        </collision>
        <collision name="Pioneer_p3dx">
            <origin rpy="1.572029 3.144074 2.581897" xyz="-0.236583 0.101323 0.054787" />
            <geometry>
                <box size="0.008465 0.030021 0.116624" />
            </geometry>
        </collision>
        <collision name="Pioneer_p3dx">
            <origin rpy="1.568016 3.140261 -1.126414" xyz="-0.156920 0.173194 0.055006" />
            <geometry>
                <box size="0.008464 0.030028 0.111812" />
            </geometry>
        </collision>
        <collision name="Pioneer_p3dx">
            <origin rpy="1.573065 3.139902 0.908026" xyz="0.167262 0.165695 0.055934" />
            <geometry>
                <box size="0.009465 0.030004 0.112502" />
            </geometry>
        </collision>
        <collision name="Pioneer_p3dx">
            <origin rpy="1.569794 3.144250 -2.807876" xyz="0.226729 0.085472 0.056113" />
            <geometry>
                <box size="0.009243 0.030005 0.101244" />
            </geometry>
        </collision>
        <collision name="Pioneer_p3dx">
            <origin rpy="1.570794 3.144454 3.122322" xyz="0.242190 -0.005745 0.056168" />
            <geometry>
                <box size="0.009243 0.030006 0.090002" />
            </geometry>
        </collision>
        <collision name="Pioneer_p3dx">
            <origin rpy="1.570061 3.138890 -0.372261" xyz="0.223227 -0.096298 0.056124" />
            <geometry>
                <box size="0.009243 0.030020 0.101248" />
            </geometry>
        </collision>
        <collision name="Pioneer_p3dx">
            <origin rpy="-1.568556 3.143361 2.195025" xyz="0.160712 -0.174170 0.055956" />
            <geometry>
                <box size="0.009465 0.030001 0.112500" />
            </geometry>
        </collision>
        <collision name="Pioneer_p3dx">
            <origin rpy="-3.139183 3.139750 0.926448" xyz="-0.153029 -0.094123 0.121440" />
            <geometry>
                <box size="0.050034 0.055540 0.120014" />
            </geometry>
        </collision>
        <collision name="Pioneer_p3dx">
            <origin rpy="3.139403 3.139562 -0.804613" xyz="0.124785 -0.090819 0.122347" />
            <geometry>
                <box size="0.050005 0.077807 0.120005" />
            </geometry>
        </collision>
        <collision name="Pioneer_p3dx">
            <origin rpy="3.139193 3.143490 -2.375035" xyz="0.128158 0.083788 0.122337" />
            <geometry>
                <box size="0.050042 0.077823 0.120005" />
            </geometry>
        </collision>
        <collision name="Pioneer_p3dx">
            <origin rpy="-1.570864 3.144400 3.121977" xyz="0.144145 -0.003841 0.122403" />
            <geometry>
                <box size="0.055040 0.120001 0.155001" />
            </geometry>
        </collision>
        <collision name="Pioneer_p3dx">
            <origin rpy="1.570834 3.138353 -0.019271" xyz="-0.165783 0.002123 0.121386" />
            <geometry>
                <box size="0.045038 0.120005 0.200003" />
            </geometry>
        </collision>
        <collision name="Pioneer_p3dx">
            <origin rpy="-1.551014 4.709148 -0.039053" xyz="-0.013322 -0.000816 0.121880" />
            <geometry>
                <box size="0.120000 0.260059 0.265000" />
            </geometry>
        </collision>
        <collision name="Pioneer_p3dx">
            <origin rpy="-1.548615 4.709493 -0.041452" xyz="0.025814 -0.001563 0.234493" />
            <geometry>
                <box size="0.005006 0.155000 0.380000" />
            </geometry>
        </collision>
        <collision name="Pioneer_p3dx">
            <origin rpy="-2.125355 4.709493 -0.042416" xyz="-0.177006 0.096763 0.233902" />
            <geometry>
                <box size="0.005000 0.068200 0.121300" />
            </geometry>
        </collision>
        <collision name="Pioneer_p3dx">
            <origin rpy="-1.548615 4.709493 -0.041452" xyz="-0.206662 0.002918 0.233827" />
            <geometry>
                <box size="0.005000 0.068200 0.121300" />
            </geometry>
        </collision>
        <collision name="Pioneer_p3dx">
            <origin rpy="-0.970500 4.709490 -0.041864" xyz="-0.180644 -0.091992 0.233914" />
            <geometry>
                <box size="0.005000 0.068200 0.121300" />
            </geometry>
        </collision>
        <collision name="Pioneer_p3dx">
            <origin rpy="0.807564 4.709493 -0.041437" xyz="-0.053530 0.163996 0.234251" />
            <geometry>
                <box size="0.005000 0.030000 0.045000" />
            </geometry>
        </collision>
        <collision name="Pioneer_p3dx">
            <origin rpy="2.378392 4.709493 -0.041469" xyz="-0.059850 -0.163942 0.234272" />
            <geometry>
                <box size="0.005000 0.030000 0.045000" />
            </geometry>
        </collision>
        <collision name="Pioneer_p3dx">
            <origin rpy="-2.321796 4.709493 -0.041452" xyz="0.105197 -0.111113 0.234743" />
            <geometry>
                <box size="0.005000 0.110000 0.121300" />
            </geometry>
        </collision>
        <collision name="Pioneer_p3dx">
            <origin rpy="-1.939569 4.709493 -0.041452" xyz="0.144096 -0.064854 0.234850" />
            <geometry>
                <box size="0.005000 0.110000 0.045000" />
            </geometry>
        </collision>
        <collision name="Pioneer_p3dx">
            <origin rpy="-1.548615 4.709493 -0.041452" xyz="0.154270 -0.004039 0.234873" />
            <geometry>
                <box size="0.005000 0.110000 0.121300" />
            </geometry>
        </collision>
        <collision name="Pioneer_p3dx">
            <origin rpy="-1.157661 4.709493 -0.041452" xyz="0.146447 0.057123 0.234843" />
            <geometry>
                <box size="0.005000 0.110000 0.045000" />
            </geometry>
        </collision>
        <collision name="Pioneer_p3dx">
            <origin rpy="-0.775369 4.709493 -0.041517" xyz="0.109360 0.104847 0.234730" />
            <geometry>
                <box size="0.005000 0.110000 0.121300" />
            </geometry>
        </collision>
        <collision name="Pioneer_p3dx">
            <origin rpy="-1.548615 4.709493 -0.041452" xyz="-0.104211 0.000943 0.234121" />
            <geometry>
                <box size="0.005001 0.140000 0.330000" />
            </geometry>
        </collision>
        <visual name="Pioneer_p3dx_visible">
            <origin rpy="3.141528 3.144488 3.122322" xyz="-0.012910 -0.000823 0.138658" />
            <geometry>
                <mesh filename="file:///root/ros2_ws/src/robotica/pioneer_Pioneer_p3dx_visible_vis_1.dae" />
            </geometry>
            <material name="Pioneer_p3dx_visible_material">
                <color rgba="0.937647 0.297647 0.310447 1.0" />
            </material>
        </visual>
        <visual name="Pioneer_p3dx_visible">
            <origin rpy="3.141528 3.144488 3.122322" xyz="-0.012910 -0.000823 0.138658" />
            <geometry>
                <mesh filename="file:///root/ros2_ws/src/robotica/pioneer_Pioneer_p3dx_visible_vis_2.dae" />
            </geometry>
            <material name="Pioneer_p3dx_visible_material">
                <color rgba="0.394118 0.394118 0.394118 1.0" />
            </material>
        </visual>
        <visual name="Pioneer_p3dx_visible">
            <origin rpy="3.141528 3.144488 3.122322" xyz="-0.012910 -0.000823 0.138658" />
            <geometry>
                <mesh filename="file:///root/ros2_ws/src/robotica/pioneer_Pioneer_p3dx_visible_vis_3.dae" />
            </geometry>
            <material name="Pioneer_p3dx_visible_material">
                <color rgba="0.394118 0.394118 0.394118 1.0" />
            </material>
        </visual>
        <visual name="Pioneer_p3dx_visible">
            <origin rpy="3.141528 3.144488 3.122322" xyz="-0.012910 -0.000823 0.138658" />
            <geometry>
                <mesh filename="file:///root/ros2_ws/src/robotica/pioneer_Pioneer_p3dx_visible_vis_4.dae" />
            </geometry>
            <material name="Pioneer_p3dx_visible_material">
                <color rgba="1.000000 0.836592 0.556463 1.0" />
            </material>
        </visual>
        <visual name="Pioneer_p3dx_visible">
            <origin rpy="3.141528 3.144488 3.122322" xyz="-0.012910 -0.000823 0.138658" />
            <geometry>
                <mesh filename="file:///root/ros2_ws/src/robotica/pioneer_Pioneer_p3dx_visible_vis_5.dae" />
            </geometry>
            <material name="Pioneer_p3dx_visible_material">
                <color rgba="0.147059 0.147059 0.147059 1.0" />
            </material>
        </visual>
        <visual name="Pioneer_p3dx_visible">
            <origin rpy="3.141528 3.144488 3.122322" xyz="-0.012910 -0.000823 0.138658" />
            <geometry>
                <mesh filename="file:///root/ros2_ws/src/robotica/pioneer_Pioneer_p3dx_visible_vis_6.dae" />
            </geometry>
            <material name="Pioneer_p3dx_visible_material">
                <color rgba="1.000000 0.836592 0.556463 1.0" />
            </material>
        </visual>
        <visual name="Pioneer_p3dx_visible">
            <origin rpy="3.141528 3.144488 3.122322" xyz="-0.012910 -0.000823 0.138658" />
            <geometry>
                <mesh filename="file:///root/ros2_ws/src/robotica/pioneer_Pioneer_p3dx_visible_vis_7.dae" />
            </geometry>
            <material name="Pioneer_p3dx_visible_material">
                <color rgba="0.147059 0.147059 0.147059 1.0" />
            </material>
        </visual>
        <visual name="Pioneer_p3dx_visible">
            <origin rpy="3.141528 3.144488 3.122322" xyz="-0.012910 -0.000823 0.138658" />
            <geometry>
                <mesh filename="file:///root/ros2_ws/src/robotica/pioneer_Pioneer_p3dx_visible_vis_8.dae" />
            </geometry>
            <material name="Pioneer_p3dx_visible_material">
                <color rgba="1.000000 0.836592 0.556463 1.0" />
            </material>
        </visual>
        <visual name="Pioneer_p3dx_visible">
            <origin rpy="3.141528 3.144488 3.122322" xyz="-0.012910 -0.000823 0.138658" />
            <geometry>
                <mesh filename="file:///root/ros2_ws/src/robotica/pioneer_Pioneer_p3dx_visible_vis_9.dae" />
            </geometry>
            <material name="Pioneer_p3dx_visible_material">
                <color rgba="0.147059 0.147059 0.147059 1.0" />
            </material>
        </visual>
        <visual name="Pioneer_p3dx_visible">
            <origin rpy="3.141528 3.144488 3.122322" xyz="-0.012910 -0.000823 0.138658" />
            <geometry>
                <mesh filename="file:///root/ros2_ws/src/robotica/pioneer_Pioneer_p3dx_visible_vis_10.dae" />
            </geometry>
            <material name="Pioneer_p3dx_visible_material">
                <color rgba="1.000000 0.836592 0.556463 1.0" />
            </material>
        </visual>
        <visual name="Pioneer_p3dx_visible">
            <origin rpy="3.141528 3.144488 3.122322" xyz="-0.012910 -0.000823 0.138658" />
            <geometry>
                <mesh filename="file:///root/ros2_ws/src/robotica/pioneer_Pioneer_p3dx_visible_vis_11.dae" />
            </geometry>
            <material name="Pioneer_p3dx_visible_material">
                <color rgba="0.147059 0.147059 0.147059 1.0" />
            </material>
        </visual>
        <visual name="Pioneer_p3dx_visible">
            <origin rpy="3.141528 3.144488 3.122322" xyz="-0.012910 -0.000823 0.138658" />
            <geometry>
                <mesh filename="file:///root/ros2_ws/src/robotica/pioneer_Pioneer_p3dx_visible_vis_12.dae" />
            </geometry>
            <material name="Pioneer_p3dx_visible_material">
                <color rgba="1.000000 0.836592 0.556463 1.0" />
            </material>
        </visual>
        <visual name="Pioneer_p3dx_visible">
            <origin rpy="3.141528 3.144488 3.122322" xyz="-0.012910 -0.000823 0.138658" />
            <geometry>
                <mesh filename="file:///root/ros2_ws/src/robotica/pioneer_Pioneer_p3dx_visible_vis_13.dae" />
            </geometry>
            <material name="Pioneer_p3dx_visible_material">
                <color rgba="0.147059 0.147059 0.147059 1.0" />
            </material>
        </visual>
        <visual name="Pioneer_p3dx_visible">
            <origin rpy="3.141528 3.144488 3.122322" xyz="-0.012910 -0.000823 0.138658" />
            <geometry>
                <mesh filename="file:///root/ros2_ws/src/robotica/pioneer_Pioneer_p3dx_visible_vis_14.dae" />
            </geometry>
            <material name="Pioneer_p3dx_visible_material">
                <color rgba="1.000000 0.836592 0.556463 1.0" />
            </material>
        </visual>
        <visual name="Pioneer_p3dx_visible">
            <origin rpy="3.141528 3.144488 3.122322" xyz="-0.012910 -0.000823 0.138658" />
            <geometry>
                <mesh filename="file:///root/ros2_ws/src/robotica/pioneer_Pioneer_p3dx_visible_vis_15.dae" />
            </geometry>
            <material name="Pioneer_p3dx_visible_material">
                <color rgba="0.147059 0.147059 0.147059 1.0" />
            </material>
        </visual>
        <visual name="Pioneer_p3dx_visible">
            <origin rpy="3.141528 3.144488 3.122322" xyz="-0.012910 -0.000823 0.138658" />
            <geometry>
                <mesh filename="file:///root/ros2_ws/src/robotica/pioneer_Pioneer_p3dx_visible_vis_16.dae" />
            </geometry>
            <material name="Pioneer_p3dx_visible_material">
                <color rgba="1.000000 0.836592 0.556463 1.0" />
            </material>
        </visual>
        <visual name="Pioneer_p3dx_visible">
            <origin rpy="3.141528 3.144488 3.122322" xyz="-0.012910 -0.000823 0.138658" />
            <geometry>
                <mesh filename="file:///root/ros2_ws/src/robotica/pioneer_Pioneer_p3dx_visible_vis_17.dae" />
            </geometry>
            <material name="Pioneer_p3dx_visible_material">
                <color rgba="0.147059 0.147059 0.147059 1.0" />
            </material>
        </visual>
        <visual name="Pioneer_p3dx_visible">
            <origin rpy="3.141528 3.144488 3.122322" xyz="-0.012910 -0.000823 0.138658" />
            <geometry>
                <mesh filename="file:///root/ros2_ws/src/robotica/pioneer_Pioneer_p3dx_visible_vis_18.dae" />
            </geometry>
            <material name="Pioneer_p3dx_visible_material">
                <color rgba="1.000000 0.836592 0.556463 1.0" />
            </material>
        </visual>
        <visual name="Pioneer_p3dx_visible">
            <origin rpy="3.141528 3.144488 3.122322" xyz="-0.012910 -0.000823 0.138658" />
            <geometry>
                <mesh filename="file:///root/ros2_ws/src/robotica/pioneer_Pioneer_p3dx_visible_vis_19.dae" />
            </geometry>
            <material name="Pioneer_p3dx_visible_material">
                <color rgba="0.147059 0.147059 0.147059 1.0" />
            </material>
        </visual>
        <visual name="Pioneer_p3dx_visible">
            <origin rpy="3.141528 3.144488 3.122322" xyz="-0.012910 -0.000823 0.138658" />
            <geometry>
                <mesh filename="file:///root/ros2_ws/src/robotica/pioneer_Pioneer_p3dx_visible_vis_20.dae" />
            </geometry>
            <material name="Pioneer_p3dx_visible_material">
                <color rgba="1.000000 0.836592 0.556463 1.0" />
            </material>
        </visual>
        <visual name="Pioneer_p3dx_visible">
            <origin rpy="3.141528 3.144488 3.122322" xyz="-0.012910 -0.000823 0.138658" />
            <geometry>
                <mesh filename="file:///root/ros2_ws/src/robotica/pioneer_Pioneer_p3dx_visible_vis_21.dae" />
            </geometry>
            <material name="Pioneer_p3dx_visible_material">
                <color rgba="0.147059 0.147059 0.147059 1.0" />
            </material>
        </visual>
        <visual name="Pioneer_p3dx_visible">
            <origin rpy="3.141528 3.144488 3.122322" xyz="-0.012910 -0.000823 0.138658" />
            <geometry>
                <mesh filename="file:///root/ros2_ws/src/robotica/pioneer_Pioneer_p3dx_visible_vis_22.dae" />
            </geometry>
            <material name="Pioneer_p3dx_visible_material">
                <color rgba="1.000000 0.836592 0.556463 1.0" />
            </material>
        </visual>
        <visual name="Pioneer_p3dx_visible">
            <origin rpy="3.141528 3.144488 3.122322" xyz="-0.012910 -0.000823 0.138658" />
            <geometry>
                <mesh filename="file:///root/ros2_ws/src/robotica/pioneer_Pioneer_p3dx_visible_vis_23.dae" />
            </geometry>
            <material name="Pioneer_p3dx_visible_material">
                <color rgba="0.147059 0.147059 0.147059 1.0" />
            </material>
        </visual>
        <visual name="Pioneer_p3dx_visible">
            <origin rpy="3.141528 3.144488 3.122322" xyz="-0.012910 -0.000823 0.138658" />
            <geometry>
                <mesh filename="file:///root/ros2_ws/src/robotica/pioneer_Pioneer_p3dx_visible_vis_24.dae" />
            </geometry>
            <material name="Pioneer_p3dx_visible_material">
                <color rgba="1.000000 0.836592 0.556463 1.0" />
            </material>
        </visual>
        <visual name="Pioneer_p3dx_visible">
            <origin rpy="3.141528 3.144488 3.122322" xyz="-0.012910 -0.000823 0.138658" />
            <geometry>
                <mesh filename="file:///root/ros2_ws/src/robotica/pioneer_Pioneer_p3dx_visible_vis_25.dae" />
            </geometry>
            <material name="Pioneer_p3dx_visible_material">
                <color rgba="0.147059 0.147059 0.147059 1.0" />
            </material>
        </visual>
        <visual name="Pioneer_p3dx_visible">
            <origin rpy="3.141528 3.144488 3.122322" xyz="-0.012910 -0.000823 0.138658" />
            <geometry>
                <mesh filename="file:///root/ros2_ws/src/robotica/pioneer_Pioneer_p3dx_visible_vis_26.dae" />
            </geometry>
            <material name="Pioneer_p3dx_visible_material">
                <color rgba="1.000000 0.836592 0.556463 1.0" />
            </material>
        </visual>
        <visual name="Pioneer_p3dx_visible">
            <origin rpy="3.141528 3.144488 3.122322" xyz="-0.012910 -0.000823 0.138658" />
            <geometry>
                <mesh filename="file:///root/ros2_ws/src/robotica/pioneer_Pioneer_p3dx_visible_vis_27.dae" />
            </geometry>
            <material name="Pioneer_p3dx_visible_material">
                <color rgba="0.147059 0.147059 0.147059 1.0" />
            </material>
        </visual>
        <visual name="Pioneer_p3dx_visible">
            <origin rpy="3.141528 3.144488 3.122322" xyz="-0.012910 -0.000823 0.138658" />
            <geometry>
                <mesh filename="file:///root/ros2_ws/src/robotica/pioneer_Pioneer_p3dx_visible_vis_28.dae" />
            </geometry>
            <material name="Pioneer_p3dx_visible_material">
                <color rgba="1.000000 0.836592 0.556463 1.0" />
            </material>
        </visual>
        <visual name="Pioneer_p3dx_visible">
            <origin rpy="3.141528 3.144488 3.122322" xyz="-0.012910 -0.000823 0.138658" />
            <geometry>
                <mesh filename="file:///root/ros2_ws/src/robotica/pioneer_Pioneer_p3dx_visible_vis_29.dae" />
            </geometry>
            <material name="Pioneer_p3dx_visible_material">
                <color rgba="0.147059 0.147059 0.147059 1.0" />
            </material>
        </visual>
        <visual name="Pioneer_p3dx_visible">
            <origin rpy="3.141528 3.144488 3.122322" xyz="-0.012910 -0.000823 0.138658" />
            <geometry>
                <mesh filename="file:///root/ros2_ws/src/robotica/pioneer_Pioneer_p3dx_visible_vis_30.dae" />
            </geometry>
            <material name="Pioneer_p3dx_visible_material">
                <color rgba="1.000000 0.836592 0.556463 1.0" />
            </material>
        </visual>
        <visual name="Pioneer_p3dx_visible">
            <origin rpy="3.141528 3.144488 3.122322" xyz="-0.012910 -0.000823 0.138658" />
            <geometry>
                <mesh filename="file:///root/ros2_ws/src/robotica/pioneer_Pioneer_p3dx_visible_vis_31.dae" />
            </geometry>
            <material name="Pioneer_p3dx_visible_material">
                <color rgba="0.147059 0.147059 0.147059 1.0" />
            </material>
        </visual>
        <visual name="Pioneer_p3dx_visible">
            <origin rpy="3.141528 3.144488 3.122322" xyz="-0.012910 -0.000823 0.138658" />
            <geometry>
                <mesh filename="file:///root/ros2_ws/src/robotica/pioneer_Pioneer_p3dx_visible_vis_32.dae" />
            </geometry>
            <material name="Pioneer_p3dx_visible_material">
                <color rgba="1.000000 0.836592 0.556463 1.0" />
            </material>
        </visual>
        <visual name="Pioneer_p3dx_visible">
            <origin rpy="3.141528 3.144488 3.122322" xyz="-0.012910 -0.000823 0.138658" />
            <geometry>
                <mesh filename="file:///root/ros2_ws/src/robotica/pioneer_Pioneer_p3dx_visible_vis_33.dae" />
            </geometry>
            <material name="Pioneer_p3dx_visible_material">
                <color rgba="0.147059 0.147059 0.147059 1.0" />
            </material>
        </visual>
        <visual name="Pioneer_p3dx_visible">
            <origin rpy="3.141528 3.144488 3.122322" xyz="-0.012910 -0.000823 0.138658" />
            <geometry>
                <mesh filename="file:///root/ros2_ws/src/robotica/pioneer_Pioneer_p3dx_visible_vis_34.dae" />
            </geometry>
            <material name="Pioneer_p3dx_visible_material">
                <color rgba="1.000000 0.836592 0.556463 1.0" />
            </material>
        </visual>
        <visual name="Pioneer_p3dx_visible">
            <origin rpy="3.141528 3.144488 3.122322" xyz="-0.012910 -0.000823 0.138658" />
            <geometry>
                <mesh filename="file:///root/ros2_ws/src/robotica/pioneer_Pioneer_p3dx_visible_vis_35.dae" />
            </geometry>
            <material name="Pioneer_p3dx_visible_material">
                <color rgba="0.147059 0.147059 0.147059 1.0" />
            </material>
        </visual>
    </link>
    <joint name="Pioneer_p3dx_rightMotor" type="continuous">
        <axis xyz="0 0 1" />
        <parent link="base_link_gt" />
        <child link="Pioneer_p3dx_rightWheel" />
        <origin rpy="1.570733 3.144833 3.122322" xyz="0.028555 -0.167155 0.097514" />
    </joint>
    <link name="Pioneer_p3dx_rightWheel">
        <inertial>
            <origin rpy="3.141592 3.141593 -3.141593" xyz="0.000000 -0.000000 -0.000000" />
            <inertia izz="0.059999998658895" iyz="0.0" iyy="0.029999999329448" ixx="0.029999999329448" ixy="0.0" ixz="0.0" />
            <mass value="1.5" />
        </inertial>
        <collision name="Pioneer_p3dx_rightWheel">
            <origin rpy="3.141592 3.141593 -3.141593" xyz="0.000000 -0.000000 -0.000000" />
            <geometry>
                <cylinder length="0.050000000745058" radius="0.097499996423721" />
            </geometry>
        </collision>
        <visual name="Pioneer_p3dx_rightWheel_visible">
            <origin rpy="-1.570797 3.141592 -3.141247" xyz="0.000000 -0.000000 -0.000000" />
            <geometry>
                <mesh filename="file:///root/ros2_ws/src/robotica/pioneer_Pioneer_p3dx_rightWheel_visible_vis_1.dae" />
            </geometry>
            <material name="Pioneer_p3dx_rightWheel_visible_material">
                <color rgba="0.279651 0.279173 0.279173 1.0" />
            </material>
        </visual>
        <visual name="Pioneer_p3dx_rightWheel_visible">
            <origin rpy="-1.570797 3.141592 -3.141247" xyz="0.000000 -0.000000 -0.000000" />
            <geometry>
                <mesh filename="file:///root/ros2_ws/src/robotica/pioneer_Pioneer_p3dx_rightWheel_visible_vis_2.dae" />
            </geometry>
            <material name="Pioneer_p3dx_rightWheel_visible_material">
                <color rgba="1.000000 0.836592 0.556463 1.0" />
            </material>
        </visual>
    </link>
    <joint name="Pioneer_p3dx_leftMotor" type="continuous">
        <axis xyz="0 0 1" />
        <parent link="base_link_gt" />
        <child link="Pioneer_p3dx_leftWheel" />
        <origin rpy="1.570733 3.144833 3.122322" xyz="0.034929 0.163783 0.097516" />
    </joint>
    <link name="Pioneer_p3dx_leftWheel">
        <inertial>
            <origin rpy="3.141592 3.141593 -3.141593" xyz="-0.000000 0.000000 0.000000" />
            <inertia izz="0.059999998658895" iyz="0.0" iyy="0.029999999329448" ixx="0.029999999329448" ixy="0.0" ixz="0.0" />
            <mass value="1.5" />
        </inertial>
        <collision name="Pioneer_p3dx_leftWheel">
            <origin rpy="3.141592 3.141593 -3.141593" xyz="-0.000000 0.000000 0.000000" />
            <geometry>
                <cylinder length="0.050000000745058" radius="0.097499996423721" />
            </geometry>
        </collision>
        <visual name="Pioneer_p3dx_leftWheel_visible">
            <origin rpy="-1.570797 3.141593 -3.141247" xyz="0.000000 -0.000000 0.000000" />
            <geometry>
                <mesh filename="file:///root/ros2_ws/src/robotica/pioneer_Pioneer_p3dx_leftWheel_visible_vis_1.dae" />
            </geometry>
            <material name="Pioneer_p3dx_leftWheel_visible_material">
                <color rgba="0.279651 0.279173 0.279173 1.0" />
            </material>
        </visual>
        <visual name="Pioneer_p3dx_leftWheel_visible">
            <origin rpy="-1.570797 3.141593 -3.141247" xyz="0.000000 -0.000000 0.000000" />
            <geometry>
                <mesh filename="file:///root/ros2_ws/src/robotica/pioneer_Pioneer_p3dx_leftWheel_visible_vis_2.dae" />
            </geometry>
            <material name="Pioneer_p3dx_leftWheel_visible_material">
                <color rgba="1.000000 0.836592 0.556463 1.0" />
            </material>
        </visual>
    </link>
    <joint name="Pioneer_p3dx_caster_freeJoint1" type="continuous">
        <axis xyz="0 0 1" />
        <parent link="base_link_gt" />
        <child link="Pioneer_p3dx_caster_link" />
        <origin rpy="3.141529 3.144833 3.122322" xyz="-0.161655 0.002039 0.060376" />
    </joint>
    <link name="Pioneer_p3dx_caster_link">
        <inertial>
            <origin rpy="3.141593 3.141593 2.847039" xyz="0.000000 -0.000000 -0.000000" />
            <inertia izz="0.019983999431133" iyz="0.0" iyy="0.016000000759959" ixx="0.016000000759959" ixy="0.0" ixz="0.0" />
            <mass value="1.0" />
        </inertial>
        <collision name="Pioneer_p3dx_caster_link">
            <origin rpy="3.141593 3.141593 2.847039" xyz="0.000000 -0.000000 -0.000000" />
            <geometry>
                <cylinder length="0.0029599245171994" radius="0.01767392642796" />
            </geometry>
        </collision>
        <visual name="Pioneer_p3dx_caster_link_visible">
            <origin rpy="-3.141593 3.141593 3.141593" xyz="0.007770 0.000000 -0.020349" />
            <geometry>
                <mesh filename="file:///root/ros2_ws/src/robotica/pioneer_Pioneer_p3dx_caster_link_visible_vis_1.dae" />
            </geometry>
            <material name="Pioneer_p3dx_caster_link_visible_material">
                <color rgba="1.000000 1.000000 1.000000 1.0" />
            </material>
        </visual>
    </link>
    <joint name="Pioneer_p3dx_caster_freeJoint2" type="continuous">
        <axis xyz="0 0 1" />
        <parent link="Pioneer_p3dx_caster_link" />
        <child link="Pioneer_p3dx_caster_wheel" />
        <origin rpy="-1.570796 3.141593 3.141593" xyz="0.022199 0.000000 -0.031079" />
    </joint>
    <link name="Pioneer_p3dx_caster_wheel">
        <inertial>
            <origin rpy="-3.141593 3.141593 -3.141593" xyz="-0.000000 0.000000 0.000000" />
            <inertia izz="0.0070088161155581" iyz="0.0" iyy="0.0010191985638812" ixx="0.0010191985638812" ixy="0.0" ixz="0.0" />
            <mass value="0.25" />
        </inertial>
        <collision name="Pioneer_p3dx_caster_wheel">
            <origin rpy="-3.141593 3.141593 -3.141593" xyz="-0.000000 0.000000 0.000000" />
            <geometry>
                <cylinder length="0.0051798284985125" radius="0.029599018394947" />
            </geometry>
        </collision>
        <visual name="Pioneer_p3dx_caster_wheel_visible">
            <origin rpy="3.141593 3.141593 3.141593" xyz="-0.000000 0.000000 0.000000" />
            <geometry>
                <cylinder length="0.02071931399405" radius="0.029599018394947" />
            </geometry>
            <material name="Pioneer_p3dx_caster_wheel_visible_material">
                <color rgba="0.305882 0.305882 0.305882 1.0" />
            </material>
        </visual>
    </link>
</robot>
