<?xml version="1.0"?>
<robot name="Pioneer_p3dx">
    <link name="base_link">
        <inertial>
            <origin rpy="3.141527 3.144474 3.139221" xyz="-0.010503 -0.001824 0.138650" />
            <inertia ixz="6.7551167532783e-30" ixy="1.3291859387186e-44" ixx="1.9199999570847" iyz="2.9803723463435e-16" izz="2.0906035900116" iyy="1.9390720129013" />
            <mass value="16.0" />
        </inertial>
        <collision name="Pioneer_p3dx">
            <origin xyz="-0.148588 0.094470 0.121423" rpy="-3.139263 3.143248 2.193493" />
            <geometry>
                <box size="0.050035 0.055540 0.120014" />
            </geometry>
        </collision>
        <collision name="Pioneer_p3dx">
            <origin xyz="0.155012 -0.066456 0.207238" rpy="1.572289 3.144422 2.615331" />
            <geometry>
                <box size="0.055000 0.055000 0.050100" />
            </geometry>
        </collision>
        <collision name="Pioneer_p3dx">
            <origin xyz="0.127875 -0.102193 0.207113" rpy="1.573165 3.143737 2.266264" />
            <geometry>
                <box size="0.055000 0.055000 0.050100" />
            </geometry>
        </collision>
        <collision name="Pioneer_p3dx">
            <origin xyz="-0.152163 -0.099899 0.206426" rpy="1.573328 3.139571 0.869959" />
            <geometry>
                <box size="0.055000 0.055000 0.050100" />
            </geometry>
        </collision>
        <collision name="Pioneer_p3dx">
            <origin xyz="-0.180754 -0.065660 0.206341" rpy="1.572528 3.138827 0.521514" />
            <geometry>
                <box size="0.055000 0.055000 0.050100" />
            </geometry>
        </collision>
        <collision name="Pioneer_p3dx">
            <origin xyz="-0.195938 -0.023684 0.206294" rpy="1.571502 3.138428 0.172932" />
            <geometry>
                <box size="0.055000 0.055000 0.050100" />
            </geometry>
        </collision>
        <collision name="Pioneer_p3dx">
            <origin xyz="-0.195832 0.020923 0.206291" rpy="1.571213 3.144789 2.963911" />
            <geometry>
                <box size="0.055000 0.055000 0.050100" />
            </geometry>
        </collision>
        <collision name="Pioneer_p3dx">
            <origin xyz="-0.180449 0.062826 0.206333" rpy="1.572289 3.144418 2.615334" />
            <geometry>
                <box size="0.055000 0.055000 0.050100" />
            </geometry>
        </collision>
        <collision name="Pioneer_p3dx">
            <origin xyz="-0.151682 0.096967 0.206413" rpy="1.573194 3.143725 2.267583" />
            <geometry>
                <box size="0.055000 0.055000 0.050100" />
            </geometry>
        </collision>
        <collision name="Pioneer_p3dx">
            <origin xyz="0.130006 0.098644 0.207155" rpy="3.138908 3.143228 -2.126080" />
            <geometry>
                <box size="0.055000 0.055000 0.050100" />
            </geometry>
        </collision>
        <collision name="Pioneer_p3dx">
            <origin xyz="0.154424 0.068540 0.207220" rpy="1.569554 3.144466 -2.694451" />
            <geometry>
                <box size="0.055000 0.055000 0.050100" />
            </geometry>
        </collision>
        <collision name="Pioneer_p3dx">
            <origin xyz="0.170490 0.020105 0.207278" rpy="1.571135 3.138904 0.171147" />
            <geometry>
                <box size="0.055000 0.055000 0.050100" />
            </geometry>
        </collision>
        <collision name="Pioneer_p3dx">
            <origin xyz="0.170370 -0.024613 0.207285" rpy="-1.570526 3.144303 2.966139" />
            <geometry>
                <box size="0.055000 0.055000 0.050100" />
            </geometry>
        </collision>
        <collision name="Pioneer_p3dx">
            <origin xyz="-0.012709 -0.001789 0.206781" rpy="-1.550341 4.709162 -0.022828" />
            <geometry>
                <box size="0.050128 0.271710 0.274352" />
            </geometry>
        </collision>
        <collision name="Pioneer_p3dx">
            <origin xyz="-0.265531 -0.001225 0.054714" rpy="-1.570790 3.138756 -0.002373" />
            <geometry>
                <box size="0.008461 0.030006 0.100002" />
            </geometry>
        </collision>
        <collision name="Pioneer_p3dx">
            <origin xyz="-0.158276 -0.172696 0.055032" rpy="-1.573299 3.142801 -2.036812" />
            <geometry>
                <box size="0.008461 0.030008 0.111805" />
            </geometry>
        </collision>
        <collision name="Pioneer_p3dx">
            <origin xyz="-0.236367 -0.099119 0.054804" rpy="1.572387 3.139187 0.538047" />
            <geometry>
                <box size="0.008459 0.030008 0.116621" />
            </geometry>
        </collision>
        <collision name="Pioneer_p3dx">
            <origin xyz="-0.235900 0.096527 0.054791" rpy="1.572020 3.144062 2.598796" />
            <geometry>
                <box size="0.008465 0.030021 0.116624" />
            </geometry>
        </collision>
        <collision name="Pioneer_p3dx">
            <origin xyz="-0.157463 0.169734 0.055009" rpy="1.568029 3.140265 -1.109515" />
            <geometry>
                <box size="0.008464 0.030028 0.111812" />
            </geometry>
        </collision>
        <collision name="Pioneer_p3dx">
            <origin xyz="0.166800 0.167714 0.055932" rpy="1.573055 3.139912 0.924924" />
            <geometry>
                <box size="0.009465 0.030004 0.112502" />
            </geometry>
        </collision>
        <collision name="Pioneer_p3dx">
            <origin xyz="0.227614 0.088508 0.056110" rpy="1.569797 3.144237 -2.790977" />
            <geometry>
                <box size="0.009243 0.030005 0.101244" />
            </geometry>
        </collision>
        <collision name="Pioneer_p3dx">
            <origin xyz="0.244614 -0.002435 0.056165" rpy="1.570792 3.144439 3.139221" />
            <geometry>
                <box size="0.009243 0.030006 0.090002" />
            </geometry>
        </collision>
        <collision name="Pioneer_p3dx">
            <origin xyz="0.227183 -0.093296 0.056122" rpy="1.570067 3.138903 -0.355362" />
            <geometry>
                <box size="0.009243 0.030020 0.101248" />
            </geometry>
        </collision>
        <collision name="Pioneer_p3dx">
            <origin xyz="0.165993 -0.172213 0.055955" rpy="-1.568568 3.143354 2.211923" />
            <geometry>
                <box size="0.009465 0.030001 0.112500" />
            </geometry>
        </collision>
        <collision name="Pioneer_p3dx">
            <origin xyz="-0.149054 -0.097479 0.121443" rpy="-3.139193 3.139760 0.943347" />
            <geometry>
                <box size="0.050034 0.055540 0.120014" />
            </geometry>
        </collision>
        <collision name="Pioneer_p3dx">
            <origin xyz="0.128664 -0.089481 0.122346" rpy="3.139414 3.139570 -0.787715" />
            <geometry>
                <box size="0.050005 0.077807 0.120005" />
            </geometry>
        </collision>
        <collision name="Pioneer_p3dx">
            <origin xyz="0.129086 0.085158 0.122336" rpy="3.139201 3.143479 -2.358136" />
            <geometry>
                <box size="0.050042 0.077823 0.120005" />
            </geometry>
        </collision>
        <collision name="Pioneer_p3dx">
            <origin xyz="0.146551 -0.002189 0.122402" rpy="-1.570865 3.144386 3.138876" />
            <geometry>
                <box size="0.055040 0.120001 0.155001" />
            </geometry>
        </collision>
        <collision name="Pioneer_p3dx">
            <origin xyz="-0.163433 -0.001463 0.121390" rpy="1.570836 3.138367 -0.002372" />
            <geometry>
                <box size="0.045038 0.120005 0.200003" />
            </geometry>
        </collision>
        <collision name="Pioneer_p3dx">
            <origin xyz="-0.010944 -0.001825 0.121882" rpy="-1.550350 4.709162 -0.022819" />
            <geometry>
                <box size="0.120000 0.260059 0.265000" />
            </geometry>
        </collision>
        <collision name="Pioneer_p3dx">
            <origin xyz="0.028201 -0.001910 0.234494" rpy="-1.547860 4.709507 -0.025309" />
            <geometry>
                <box size="0.005006 0.155000 0.380000" />
            </geometry>
        </collision>
        <collision name="Pioneer_p3dx">
            <origin xyz="-0.176252 0.092975 0.233905" rpy="-2.124595 4.709507 -0.026277" />
            <geometry>
                <box size="0.005000 0.068200 0.121300" />
            </geometry>
        </collision>
        <collision name="Pioneer_p3dx">
            <origin xyz="-0.204318 -0.001358 0.233831" rpy="-1.547860 4.709507 -0.025309" />
            <geometry>
                <box size="0.005000 0.068200 0.121300" />
            </geometry>
        </collision>
        <collision name="Pioneer_p3dx">
            <origin xyz="-0.176700 -0.095814 0.233918" rpy="-0.969743 4.709505 -0.025722" />
            <geometry>
                <box size="0.005000 0.068200 0.121300" />
            </geometry>
        </collision>
        <collision name="Pioneer_p3dx">
            <origin xyz="-0.053930 0.162285 0.234253" rpy="0.808320 4.709507 -0.025294" />
            <geometry>
                <box size="0.005000 0.030000 0.045000" />
            </geometry>
        </collision>
        <collision name="Pioneer_p3dx">
            <origin xyz="-0.054708 -0.165714 0.234274" rpy="2.379148 4.709507 -0.025326" />
            <geometry>
                <box size="0.005000 0.030000 0.045000" />
            </geometry>
        </collision>
        <collision name="Pioneer_p3dx">
            <origin xyz="0.109424 -0.110103 0.234743" rpy="-2.321040 4.709507 -0.025309" />
            <geometry>
                <box size="0.005000 0.110000 0.121300" />
            </geometry>
        </collision>
        <collision name="Pioneer_p3dx">
            <origin xyz="0.147535 -0.063193 0.234850" rpy="-1.938813 4.709507 -0.025309" />
            <geometry>
                <box size="0.005000 0.110000 0.045000" />
            </geometry>
        </collision>
        <collision name="Pioneer_p3dx">
            <origin xyz="0.156680 -0.002215 0.234872" rpy="-1.547860 4.709507 -0.025309" />
            <geometry>
                <box size="0.005000 0.110000 0.121300" />
            </geometry>
        </collision>
        <collision name="Pioneer_p3dx">
            <origin xyz="0.147825 0.058806 0.234842" rpy="-1.156906 4.709507 -0.025309" />
            <geometry>
                <box size="0.005000 0.110000 0.045000" />
            </geometry>
        </collision>
        <collision name="Pioneer_p3dx">
            <origin xyz="0.109936 0.105896 0.234729" rpy="-0.774613 4.709507 -0.025374" />
            <geometry>
                <box size="0.005000 0.110000 0.121300" />
            </geometry>
        </collision>
        <collision name="Pioneer_p3dx">
            <origin xyz="-0.101848 -0.001602 0.234124" rpy="-1.547860 4.709507 -0.025309" />
            <geometry>
                <box size="0.005001 0.140000 0.330000" />
            </geometry>
        </collision>
        <visual name="Pioneer_p3dx_visible">
            <origin xyz="-0.010532 -0.001825 0.138660" rpy="3.141527 3.144474 3.139221" />
            <geometry>
                <mesh filename="file:///root/ros2_ws/src/robotica/ros_intro/coppeliaSim/base_link_Pioneer_p3dx_visible_vis_1.dae" />
            </geometry>
            <material name="Pioneer_p3dx_visible_material">
                <color rgba="0.937647 0.297647 0.310447 1.0" />
            </material>
        </visual>
        <visual name="Pioneer_p3dx_visible">
            <origin xyz="-0.010532 -0.001825 0.138660" rpy="3.141527 3.144474 3.139221" />
            <geometry>
                <mesh filename="file:///root/ros2_ws/src/robotica/ros_intro/coppeliaSim/base_link_Pioneer_p3dx_visible_vis_2.dae" />
            </geometry>
            <material name="Pioneer_p3dx_visible_material">
                <color rgba="0.394118 0.394118 0.394118 1.0" />
            </material>
        </visual>
        <visual name="Pioneer_p3dx_visible">
            <origin xyz="-0.010532 -0.001825 0.138660" rpy="3.141527 3.144474 3.139221" />
            <geometry>
                <mesh filename="file:///root/ros2_ws/src/robotica/ros_intro/coppeliaSim/base_link_Pioneer_p3dx_visible_vis_3.dae" />
            </geometry>
            <material name="Pioneer_p3dx_visible_material">
                <color rgba="0.394118 0.394118 0.394118 1.0" />
            </material>
        </visual>
        <visual name="Pioneer_p3dx_visible">
            <origin xyz="-0.010532 -0.001825 0.138660" rpy="3.141527 3.144474 3.139221" />
            <geometry>
                <mesh filename="file:///root/ros2_ws/src/robotica/ros_intro/coppeliaSim/base_link_Pioneer_p3dx_visible_vis_4.dae" />
            </geometry>
            <material name="Pioneer_p3dx_visible_material">
                <color rgba="1.000000 0.836592 0.556463 1.0" />
            </material>
        </visual>
        <visual name="Pioneer_p3dx_visible">
            <origin xyz="-0.010532 -0.001825 0.138660" rpy="3.141527 3.144474 3.139221" />
            <geometry>
                <mesh filename="file:///root/ros2_ws/src/robotica/ros_intro/coppeliaSim/base_link_Pioneer_p3dx_visible_vis_5.dae" />
            </geometry>
            <material name="Pioneer_p3dx_visible_material">
                <color rgba="0.147059 0.147059 0.147059 1.0" />
            </material>
        </visual>
        <visual name="Pioneer_p3dx_visible">
            <origin xyz="-0.010532 -0.001825 0.138660" rpy="3.141527 3.144474 3.139221" />
            <geometry>
                <mesh filename="file:///root/ros2_ws/src/robotica/ros_intro/coppeliaSim/base_link_Pioneer_p3dx_visible_vis_6.dae" />
            </geometry>
            <material name="Pioneer_p3dx_visible_material">
                <color rgba="1.000000 0.836592 0.556463 1.0" />
            </material>
        </visual>
        <visual name="Pioneer_p3dx_visible">
            <origin xyz="-0.010532 -0.001825 0.138660" rpy="3.141527 3.144474 3.139221" />
            <geometry>
                <mesh filename="file:///root/ros2_ws/src/robotica/ros_intro/coppeliaSim/base_link_Pioneer_p3dx_visible_vis_7.dae" />
            </geometry>
            <material name="Pioneer_p3dx_visible_material">
                <color rgba="0.147059 0.147059 0.147059 1.0" />
            </material>
        </visual>
        <visual name="Pioneer_p3dx_visible">
            <origin xyz="-0.010532 -0.001825 0.138660" rpy="3.141527 3.144474 3.139221" />
            <geometry>
                <mesh filename="file:///root/ros2_ws/src/robotica/ros_intro/coppeliaSim/base_link_Pioneer_p3dx_visible_vis_8.dae" />
            </geometry>
            <material name="Pioneer_p3dx_visible_material">
                <color rgba="1.000000 0.836592 0.556463 1.0" />
            </material>
        </visual>
        <visual name="Pioneer_p3dx_visible">
            <origin xyz="-0.010532 -0.001825 0.138660" rpy="3.141527 3.144474 3.139221" />
            <geometry>
                <mesh filename="file:///root/ros2_ws/src/robotica/ros_intro/coppeliaSim/base_link_Pioneer_p3dx_visible_vis_9.dae" />
            </geometry>
            <material name="Pioneer_p3dx_visible_material">
                <color rgba="0.147059 0.147059 0.147059 1.0" />
            </material>
        </visual>
        <visual name="Pioneer_p3dx_visible">
            <origin xyz="-0.010532 -0.001825 0.138660" rpy="3.141527 3.144474 3.139221" />
            <geometry>
                <mesh filename="file:///root/ros2_ws/src/robotica/ros_intro/coppeliaSim/base_link_Pioneer_p3dx_visible_vis_10.dae" />
            </geometry>
            <material name="Pioneer_p3dx_visible_material">
                <color rgba="1.000000 0.836592 0.556463 1.0" />
            </material>
        </visual>
        <visual name="Pioneer_p3dx_visible">
            <origin xyz="-0.010532 -0.001825 0.138660" rpy="3.141527 3.144474 3.139221" />
            <geometry>
                <mesh filename="file:///root/ros2_ws/src/robotica/ros_intro/coppeliaSim/base_link_Pioneer_p3dx_visible_vis_11.dae" />
            </geometry>
            <material name="Pioneer_p3dx_visible_material">
                <color rgba="0.147059 0.147059 0.147059 1.0" />
            </material>
        </visual>
        <visual name="Pioneer_p3dx_visible">
            <origin xyz="-0.010532 -0.001825 0.138660" rpy="3.141527 3.144474 3.139221" />
            <geometry>
                <mesh filename="file:///root/ros2_ws/src/robotica/ros_intro/coppeliaSim/base_link_Pioneer_p3dx_visible_vis_12.dae" />
            </geometry>
            <material name="Pioneer_p3dx_visible_material">
                <color rgba="1.000000 0.836592 0.556463 1.0" />
            </material>
        </visual>
        <visual name="Pioneer_p3dx_visible">
            <origin xyz="-0.010532 -0.001825 0.138660" rpy="3.141527 3.144474 3.139221" />
            <geometry>
                <mesh filename="file:///root/ros2_ws/src/robotica/ros_intro/coppeliaSim/base_link_Pioneer_p3dx_visible_vis_13.dae" />
            </geometry>
            <material name="Pioneer_p3dx_visible_material">
                <color rgba="0.147059 0.147059 0.147059 1.0" />
            </material>
        </visual>
        <visual name="Pioneer_p3dx_visible">
            <origin xyz="-0.010532 -0.001825 0.138660" rpy="3.141527 3.144474 3.139221" />
            <geometry>
                <mesh filename="file:///root/ros2_ws/src/robotica/ros_intro/coppeliaSim/base_link_Pioneer_p3dx_visible_vis_14.dae" />
            </geometry>
            <material name="Pioneer_p3dx_visible_material">
                <color rgba="1.000000 0.836592 0.556463 1.0" />
            </material>
        </visual>
        <visual name="Pioneer_p3dx_visible">
            <origin xyz="-0.010532 -0.001825 0.138660" rpy="3.141527 3.144474 3.139221" />
            <geometry>
                <mesh filename="file:///root/ros2_ws/src/robotica/ros_intro/coppeliaSim/base_link_Pioneer_p3dx_visible_vis_15.dae" />
            </geometry>
            <material name="Pioneer_p3dx_visible_material">
                <color rgba="0.147059 0.147059 0.147059 1.0" />
            </material>
        </visual>
        <visual name="Pioneer_p3dx_visible">
            <origin xyz="-0.010532 -0.001825 0.138660" rpy="3.141527 3.144474 3.139221" />
            <geometry>
                <mesh filename="file:///root/ros2_ws/src/robotica/ros_intro/coppeliaSim/base_link_Pioneer_p3dx_visible_vis_16.dae" />
            </geometry>
            <material name="Pioneer_p3dx_visible_material">
                <color rgba="1.000000 0.836592 0.556463 1.0" />
            </material>
        </visual>
        <visual name="Pioneer_p3dx_visible">
            <origin xyz="-0.010532 -0.001825 0.138660" rpy="3.141527 3.144474 3.139221" />
            <geometry>
                <mesh filename="file:///root/ros2_ws/src/robotica/ros_intro/coppeliaSim/base_link_Pioneer_p3dx_visible_vis_17.dae" />
            </geometry>
            <material name="Pioneer_p3dx_visible_material">
                <color rgba="0.147059 0.147059 0.147059 1.0" />
            </material>
        </visual>
        <visual name="Pioneer_p3dx_visible">
            <origin xyz="-0.010532 -0.001825 0.138660" rpy="3.141527 3.144474 3.139221" />
            <geometry>
                <mesh filename="file:///root/ros2_ws/src/robotica/ros_intro/coppeliaSim/base_link_Pioneer_p3dx_visible_vis_18.dae" />
            </geometry>
            <material name="Pioneer_p3dx_visible_material">
                <color rgba="1.000000 0.836592 0.556463 1.0" />
            </material>
        </visual>
        <visual name="Pioneer_p3dx_visible">
            <origin xyz="-0.010532 -0.001825 0.138660" rpy="3.141527 3.144474 3.139221" />
            <geometry>
                <mesh filename="file:///root/ros2_ws/src/robotica/ros_intro/coppeliaSim/base_link_Pioneer_p3dx_visible_vis_19.dae" />
            </geometry>
            <material name="Pioneer_p3dx_visible_material">
                <color rgba="0.147059 0.147059 0.147059 1.0" />
            </material>
        </visual>
        <visual name="Pioneer_p3dx_visible">
            <origin xyz="-0.010532 -0.001825 0.138660" rpy="3.141527 3.144474 3.139221" />
            <geometry>
                <mesh filename="file:///root/ros2_ws/src/robotica/ros_intro/coppeliaSim/base_link_Pioneer_p3dx_visible_vis_20.dae" />
            </geometry>
            <material name="Pioneer_p3dx_visible_material">
                <color rgba="1.000000 0.836592 0.556463 1.0" />
            </material>
        </visual>
        <visual name="Pioneer_p3dx_visible">
            <origin xyz="-0.010532 -0.001825 0.138660" rpy="3.141527 3.144474 3.139221" />
            <geometry>
                <mesh filename="file:///root/ros2_ws/src/robotica/ros_intro/coppeliaSim/base_link_Pioneer_p3dx_visible_vis_21.dae" />
            </geometry>
            <material name="Pioneer_p3dx_visible_material">
                <color rgba="0.147059 0.147059 0.147059 1.0" />
            </material>
        </visual>
        <visual name="Pioneer_p3dx_visible">
            <origin xyz="-0.010532 -0.001825 0.138660" rpy="3.141527 3.144474 3.139221" />
            <geometry>
                <mesh filename="file:///root/ros2_ws/src/robotica/ros_intro/coppeliaSim/base_link_Pioneer_p3dx_visible_vis_22.dae" />
            </geometry>
            <material name="Pioneer_p3dx_visible_material">
                <color rgba="1.000000 0.836592 0.556463 1.0" />
            </material>
        </visual>
        <visual name="Pioneer_p3dx_visible">
            <origin xyz="-0.010532 -0.001825 0.138660" rpy="3.141527 3.144474 3.139221" />
            <geometry>
                <mesh filename="file:///root/ros2_ws/src/robotica/ros_intro/coppeliaSim/base_link_Pioneer_p3dx_visible_vis_23.dae" />
            </geometry>
            <material name="Pioneer_p3dx_visible_material">
                <color rgba="0.147059 0.147059 0.147059 1.0" />
            </material>
        </visual>
        <visual name="Pioneer_p3dx_visible">
            <origin xyz="-0.010532 -0.001825 0.138660" rpy="3.141527 3.144474 3.139221" />
            <geometry>
                <mesh filename="file:///root/ros2_ws/src/robotica/ros_intro/coppeliaSim/base_link_Pioneer_p3dx_visible_vis_24.dae" />
            </geometry>
            <material name="Pioneer_p3dx_visible_material">
                <color rgba="1.000000 0.836592 0.556463 1.0" />
            </material>
        </visual>
        <visual name="Pioneer_p3dx_visible">
            <origin xyz="-0.010532 -0.001825 0.138660" rpy="3.141527 3.144474 3.139221" />
            <geometry>
                <mesh filename="file:///root/ros2_ws/src/robotica/ros_intro/coppeliaSim/base_link_Pioneer_p3dx_visible_vis_25.dae" />
            </geometry>
            <material name="Pioneer_p3dx_visible_material">
                <color rgba="0.147059 0.147059 0.147059 1.0" />
            </material>
        </visual>
        <visual name="Pioneer_p3dx_visible">
            <origin xyz="-0.010532 -0.001825 0.138660" rpy="3.141527 3.144474 3.139221" />
            <geometry>
                <mesh filename="file:///root/ros2_ws/src/robotica/ros_intro/coppeliaSim/base_link_Pioneer_p3dx_visible_vis_26.dae" />
            </geometry>
            <material name="Pioneer_p3dx_visible_material">
                <color rgba="1.000000 0.836592 0.556463 1.0" />
            </material>
        </visual>
        <visual name="Pioneer_p3dx_visible">
            <origin xyz="-0.010532 -0.001825 0.138660" rpy="3.141527 3.144474 3.139221" />
            <geometry>
                <mesh filename="file:///root/ros2_ws/src/robotica/ros_intro/coppeliaSim/base_link_Pioneer_p3dx_visible_vis_27.dae" />
            </geometry>
            <material name="Pioneer_p3dx_visible_material">
                <color rgba="0.147059 0.147059 0.147059 1.0" />
            </material>
        </visual>
        <visual name="Pioneer_p3dx_visible">
            <origin xyz="-0.010532 -0.001825 0.138660" rpy="3.141527 3.144474 3.139221" />
            <geometry>
                <mesh filename="file:///root/ros2_ws/src/robotica/ros_intro/coppeliaSim/base_link_Pioneer_p3dx_visible_vis_28.dae" />
            </geometry>
            <material name="Pioneer_p3dx_visible_material">
                <color rgba="1.000000 0.836592 0.556463 1.0" />
            </material>
        </visual>
        <visual name="Pioneer_p3dx_visible">
            <origin xyz="-0.010532 -0.001825 0.138660" rpy="3.141527 3.144474 3.139221" />
            <geometry>
                <mesh filename="file:///root/ros2_ws/src/robotica/ros_intro/coppeliaSim/base_link_Pioneer_p3dx_visible_vis_29.dae" />
            </geometry>
            <material name="Pioneer_p3dx_visible_material">
                <color rgba="0.147059 0.147059 0.147059 1.0" />
            </material>
        </visual>
        <visual name="Pioneer_p3dx_visible">
            <origin xyz="-0.010532 -0.001825 0.138660" rpy="3.141527 3.144474 3.139221" />
            <geometry>
                <mesh filename="file:///root/ros2_ws/src/robotica/ros_intro/coppeliaSim/base_link_Pioneer_p3dx_visible_vis_30.dae" />
            </geometry>
            <material name="Pioneer_p3dx_visible_material">
                <color rgba="1.000000 0.836592 0.556463 1.0" />
            </material>
        </visual>
        <visual name="Pioneer_p3dx_visible">
            <origin xyz="-0.010532 -0.001825 0.138660" rpy="3.141527 3.144474 3.139221" />
            <geometry>
                <mesh filename="file:///root/ros2_ws/src/robotica/ros_intro/coppeliaSim/base_link_Pioneer_p3dx_visible_vis_31.dae" />
            </geometry>
            <material name="Pioneer_p3dx_visible_material">
                <color rgba="0.147059 0.147059 0.147059 1.0" />
            </material>
        </visual>
        <visual name="Pioneer_p3dx_visible">
            <origin xyz="-0.010532 -0.001825 0.138660" rpy="3.141527 3.144474 3.139221" />
            <geometry>
                <mesh filename="file:///root/ros2_ws/src/robotica/ros_intro/coppeliaSim/base_link_Pioneer_p3dx_visible_vis_32.dae" />
            </geometry>
            <material name="Pioneer_p3dx_visible_material">
                <color rgba="1.000000 0.836592 0.556463 1.0" />
            </material>
        </visual>
        <visual name="Pioneer_p3dx_visible">
            <origin xyz="-0.010532 -0.001825 0.138660" rpy="3.141527 3.144474 3.139221" />
            <geometry>
                <mesh filename="file:///root/ros2_ws/src/robotica/ros_intro/coppeliaSim/base_link_Pioneer_p3dx_visible_vis_33.dae" />
            </geometry>
            <material name="Pioneer_p3dx_visible_material">
                <color rgba="0.147059 0.147059 0.147059 1.0" />
            </material>
        </visual>
        <visual name="Pioneer_p3dx_visible">
            <origin xyz="-0.010532 -0.001825 0.138660" rpy="3.141527 3.144474 3.139221" />
            <geometry>
                <mesh filename="file:///root/ros2_ws/src/robotica/ros_intro/coppeliaSim/base_link_Pioneer_p3dx_visible_vis_34.dae" />
            </geometry>
            <material name="Pioneer_p3dx_visible_material">
                <color rgba="1.000000 0.836592 0.556463 1.0" />
            </material>
        </visual>
        <visual name="Pioneer_p3dx_visible">
            <origin xyz="-0.010532 -0.001825 0.138660" rpy="3.141527 3.144474 3.139221" />
            <geometry>
                <mesh filename="file:///root/ros2_ws/src/robotica/ros_intro/coppeliaSim/base_link_Pioneer_p3dx_visible_vis_35.dae" />
            </geometry>
            <material name="Pioneer_p3dx_visible_material">
                <color rgba="0.147059 0.147059 0.147059 1.0" />
            </material>
        </visual>
    </link>
    <joint name="Pioneer_p3dx_rightMotor" type="continuous">
        <axis xyz="0 0 1" />
        <parent link="base_link" />
        <child link="Pioneer_p3dx_rightWheel" />
        <origin xyz="0.033737 -0.167433 0.097515" rpy="1.570731 3.144819 3.139221" />
    </joint>
    <link name="Pioneer_p3dx_rightWheel">
        <inertial>
            <origin rpy="3.141592 3.141593 -3.141593" xyz="0.000000 -0.000000 -0.000000" />
            <inertia ixz="0.0" ixy="0.0" ixx="0.029999999329448" iyz="0.0" izz="0.059999998658895" iyy="0.029999999329448" />
            <mass value="1.5" />
        </inertial>
        <collision name="Pioneer_p3dx_rightWheel">
            <origin xyz="0.000000 -0.000000 -0.000000" rpy="3.141592 3.141593 -3.141593" />
            <geometry>
                <cylinder radius="0.097499996423721" length="0.050000000745058" />
            </geometry>
        </collision>
        <visual name="Pioneer_p3dx_rightWheel_visible">
            <origin xyz="0.000000 -0.000000 -0.000000" rpy="-1.570797 3.141592 -3.141247" />
            <geometry>
                <mesh filename="file:///root/ros2_ws/src/robotica/ros_intro/coppeliaSim/base_link_Pioneer_p3dx_rightWheel_visible_vis_1.dae" />
            </geometry>
            <material name="Pioneer_p3dx_rightWheel_visible_material">
                <color rgba="0.279651 0.279173 0.279173 1.0" />
            </material>
        </visual>
        <visual name="Pioneer_p3dx_rightWheel_visible">
            <origin xyz="0.000000 -0.000000 -0.000000" rpy="-1.570797 3.141592 -3.141247" />
            <geometry>
                <mesh filename="file:///root/ros2_ws/src/robotica/ros_intro/coppeliaSim/base_link_Pioneer_p3dx_rightWheel_visible_vis_2.dae" />
            </geometry>
            <material name="Pioneer_p3dx_rightWheel_visible_material">
                <color rgba="1.000000 0.836592 0.556463 1.0" />
            </material>
        </visual>
    </link>
    <joint name="Pioneer_p3dx_leftMotor" type="continuous">
        <axis xyz="0 0 1" />
        <parent link="base_link" />
        <child link="Pioneer_p3dx_leftWheel" />
        <origin xyz="0.034518 0.163566 0.097516" rpy="1.570731 3.144819 3.139221" />
    </joint>
    <link name="Pioneer_p3dx_leftWheel">
        <inertial>
            <origin rpy="3.141592 3.141593 -3.141593" xyz="-0.000000 0.000000 0.000000" />
            <inertia ixz="0.0" ixy="0.0" ixx="0.029999999329448" iyz="0.0" izz="0.059999998658895" iyy="0.029999999329448" />
            <mass value="1.5" />
        </inertial>
        <collision name="Pioneer_p3dx_leftWheel">
            <origin xyz="-0.000000 0.000000 0.000000" rpy="3.141592 3.141593 -3.141593" />
            <geometry>
                <cylinder radius="0.097499996423721" length="0.050000000745058" />
            </geometry>
        </collision>
        <visual name="Pioneer_p3dx_leftWheel_visible">
            <origin xyz="0.000000 -0.000000 0.000000" rpy="-1.570797 3.141593 -3.141247" />
            <geometry>
                <mesh filename="file:///root/ros2_ws/src/robotica/ros_intro/coppeliaSim/base_link_Pioneer_p3dx_leftWheel_visible_vis_1.dae" />
            </geometry>
            <material name="Pioneer_p3dx_leftWheel_visible_material">
                <color rgba="0.279651 0.279173 0.279173 1.0" />
            </material>
        </visual>
        <visual name="Pioneer_p3dx_leftWheel_visible">
            <origin xyz="0.000000 -0.000000 0.000000" rpy="-1.570797 3.141593 -3.141247" />
            <geometry>
                <mesh filename="file:///root/ros2_ws/src/robotica/ros_intro/coppeliaSim/base_link_Pioneer_p3dx_leftWheel_visible_vis_2.dae" />
            </geometry>
            <material name="Pioneer_p3dx_leftWheel_visible_material">
                <color rgba="1.000000 0.836592 0.556463 1.0" />
            </material>
        </visual>
    </link>
    <joint name="Pioneer_p3dx_caster_freeJoint1" type="continuous">
        <axis xyz="0 0 1" />
        <parent link="base_link" />
        <child link="Pioneer_p3dx_caster_link" />
        <origin xyz="-0.159305 -0.001477 0.060379" rpy="3.141527 3.144819 3.139221" />
    </joint>
    <link name="Pioneer_p3dx_caster_link">
        <inertial>
            <origin rpy="3.141593 3.141593 2.847039" xyz="0.000000 -0.000000 -0.000000" />
            <inertia ixz="0.0" ixy="0.0" ixx="0.016000000759959" iyz="0.0" izz="0.019983999431133" iyy="0.016000000759959" />
            <mass value="1.0" />
        </inertial>
        <collision name="Pioneer_p3dx_caster_link">
            <origin xyz="0.000000 -0.000000 -0.000000" rpy="3.141593 3.141593 2.847039" />
            <geometry>
                <cylinder radius="0.01767392642796" length="0.0029599245171994" />
            </geometry>
        </collision>
        <visual name="Pioneer_p3dx_caster_link_visible">
            <origin xyz="0.007770 0.000000 -0.020349" rpy="-3.141593 3.141593 3.141593" />
            <geometry>
                <mesh filename="file:///root/ros2_ws/src/robotica/ros_intro/coppeliaSim/base_link_Pioneer_p3dx_caster_link_visible_vis_1.dae" />
            </geometry>
            <material name="Pioneer_p3dx_caster_link_visible_material">
                <color rgba="1.000000 1.000000 1.000000 1.0" />
            </material>
        </visual>
    </link>
    <joint name="Pioneer_p3dx_caster_freeJoint2" type="continuous">
        <axis xyz="0 0 1" />
        <parent link="Pioneer_p3dx_caster_link" />
        <child link="Pioneer_p3dx_caster_wheel" />
        <origin xyz="0.022199 0.000000 -0.031079" rpy="-1.570796 3.141593 3.141593" />
    </joint>
    <link name="Pioneer_p3dx_caster_wheel">
        <inertial>
            <origin rpy="-3.141593 3.141593 -3.141593" xyz="-0.000000 0.000000 0.000000" />
            <inertia ixz="0.0" ixy="0.0" ixx="0.0010191985638812" iyz="0.0" izz="0.0070088161155581" iyy="0.0010191985638812" />
            <mass value="0.25" />
        </inertial>
        <collision name="Pioneer_p3dx_caster_wheel">
            <origin xyz="-0.000000 0.000000 0.000000" rpy="-3.141593 3.141593 -3.141593" />
            <geometry>
                <cylinder radius="0.029599018394947" length="0.0051798284985125" />
            </geometry>
        </collision>
        <visual name="Pioneer_p3dx_caster_wheel_visible">
            <origin xyz="-0.000000 0.000000 0.000000" rpy="3.141593 3.141593 3.141593" />
            <geometry>
                <cylinder radius="0.029599018394947" length="0.02071931399405" />
            </geometry>
            <material name="Pioneer_p3dx_caster_wheel_visible_material">
                <color rgba="0.305882 0.305882 0.305882 1.0" />
            </material>
        </visual>
    </link>
</robot>
